Workbook

Sheet Instructions
A1: Digital Task Intensity (DTI) — Human Coder Form, NCO-2015 occupations
A2: 3,450 occupations (all NCO-2015 8-digit occupations with descriptions in Vol II). Code each occupation on the "Coding" sheet. Yellow cells are for your answers.
A4: Coder details
B5: Coder name
B6: Coder ID
B7: Date started
B8: Date finished
A10: Rules
A11: 1. | B11: Scale for Q2–Q6: 0 = none · 1 = incidental (occasional, simple) · 2 = regular, basic · 3 = regular, advanced / job-specific · 4 = core (this is the main work).
A12: 2. | B12: Score only from the occupation text; if the text is silent, score 0.
A13: 3. | B13: Q7: for every Q2–Q6 score of 1 or more, copy the exact words from the description into the matching Q7 evidence column. Leave it blank for a score of 0. A missing quote turns the cell orange.
A14: 4. | B14: Q8: give one confidence value (1 low, 2 medium, 3 high) for each of Q2–Q6, in the five Q8 columns.
A15: 5. | B15: Q9 is your overall judgement on 0–10. Do not add up Q2–Q6.
A16: 6. | B16: Q11 is the only question where you use your own knowledge of India today rather than the text.
A17: 7. | B17: Code blind: do not look at LLM scores or other coders' sheets. Do not edit the grey columns.
A18: 8. | B18: The Status column updates itself: Not started → Incomplete → Add evidence → Complete.
A20: Questions
A21: Q | B21: Question | C21: Answer format | D21: Where to enter | E21: Example answer (Accounts Clerk below)
A22: Q1 | B22: Is the description detailed enough to judge digital tasks? | C22: Yes / Partly / No | D22: Q1 column | E22: Yes
A23: Q2 | B23: Basic digital operation: routine use of computers, phones, POS/billing machines, standard software. | C23: 0–4 | D23: Q2 column | E23: 2
A24: Q3 | B24: Digital information processing: searching, recording, managing, analysing digital information. | C24: 0–4 | D24: Q3 column | E24: 3
A25: Q4 | B25: Digital communication & collaboration: e-mail, messaging, video calls, platforms/portals (voice calls do not count). | C25: 0–4 | D25: Q4 column | E25: 2
A26: Q5 | B26: Advanced / specialised digital tools: job-specific software, programming, CAD, GIS, analytics, CNC/PLC systems. | C26: 0–4 | D26: Q5 column | E26: 2
A27: Q6 | B27: Digital problem solving & content creation: creating digital content or solving non-routine problems with digital tools. | C27: 0–4 | D27: Q6 column | E27: 1
A28: Q7 | B28: For each score of 1 or more, which words in the text support it? | C28: Exact words from the text | D28: Five "Q7 evidence" columns | E28: Q2 "accounting software"; Q3 "bank reconciliation statements"; Q4 "by e-mail"; Q5 "accounting software"; Q6 "prepares vouchers, invoices"
A29: Q8 | B29: How confident are you in each of the five scores (Q2–Q6)? | C29: 1 low · 2 medium · 3 high | D29: Five "Q8 confidence" columns | E29: 3, 3, 3, 2, 2
A30: Q9 | B30: Overall, how digital is this occupation? (do not add up Q2–Q6) | C30: 0–10 | D30: Q9 column | E30: 5
A31: Q10 | B31: Is digital work core to the job or a supporting tool? | C31: Core / Supporting / Not relevant | D31: Q10 column | E31: Supporting
A32: Q11 | B32: From your own knowledge: in India today, is this job more digital than the text suggests, the same, or less? | C32: More / Same / Less | D32: Q11 column | E32: More
A33: Q12 | B33: Anything unclear or not fitting the rules? | C33: Short comment (optional) | D33: Q12 column | E33: —
A35: Worked example — Accounts Clerk (illustrative text)
B36: "Records financial transactions in ledgers and accounting software; prepares vouchers, invoices and bank reconciliation statements; maintains digital files of bills and receipts; corresponds with vendors by e-mail regarding payments; prints and files monthly summary reports."
A38: Data source
B39: Occupation titles and descriptions: National Classification of Occupations 2015, Vol II-A and II-B (Ministry of Labour & Employment, DGE). Hierarchy titles and NCO-2004 concordance: NCO-2015 Vol I.
B40: Machine-readable base table: "2015 NCO Draft Data Table" (gilesd-j.com blog, Nov 2025), checked against the official PDFs (median 100% word overlap); 2 duplicate rows removed, 3 missing and 4 cut-off descriptions restored from Vol II.
B41: Reference columns: Group (3-digit) is the level used in PLFS since July 2021. NCO skill level is by division (Div 2 = 4, Div 3 = 3, Div 4–8 = 2, Div 9 = 1; Div 1 not defined). Division 0 (Armed Forces) has no occupation descriptions in Vol II and is not included.

Sheet Coding
A1: OCCUPATION (read only) | E1: Q1 | F1: Q2–Q6 SCORES (0–4) | K1: Q7 EVIDENCE — exact words from the description | P1: Q8 CONFIDENCE (1–3) | U1: Q9–Q12 | Y1: CHECK | Z1: REFERENCE (read only)
A2: Row | B2: NCO-2015 code | C2: Occupation title | D2: Occupation description (NCO-2015 Vol II) | E2: Q1 Detail enough? | F2: Q2 Basic digital operation | G2: Q3 Digital information processing | H2: Q4 Digital communication & collaboration | I2: Q5 Advanced / specialised digital tools | J2: Q6 Digital problem solving & content creation | K2: Q7 evidence for Q2 | L2: Q7 evidence for Q3 | M2: Q7 evidence for Q4 | N2: Q7 evidence for Q5 | O2: Q7 evidence for Q6 | P2: Q8 confidence Q2 | Q2: Q8 confidence Q3 | R2: Q8 confidence Q4 | S2: Q8 confidence Q5 | T2: Q8 confidence Q6 | U2: Q9 Overall (0–10) | V2: Q10 Core / Supporting | W2: Q11 India today vs text | X2: Q12 Comment (optional) | Y2: Status | Z2: Family code (4-digit) | AA2: Family title | AB2: Group code (3-digit, PLFS level) | AC2: Group title | AD2: Division | AE2: Division title | AF2: NCO skill level | AG2: NCO-2004 code | AH2: QP/NOS reference | AI2: NSQF level
A3: 1 | B3: 1111.0100 | C3: Elected Official, Union Government | D3: Elected Official, Union Government serves in various capacities in legislative and executive branches of Union Government. Performs administrative, executive or advisory functions, which include serving as head of the Indian Union; presiding over deliberations of Houses of Parliament; leading council of ministers of Union Government; shaping, determining and defining government policies and directing their application and execution through departmental heads; representing interests of voters in Parliament, on committees and commissions; and taking part in making, amending or repealing laws. Is designated according to work performed or post held, such as: PRESIDENT OF INDIA; RASHTRAPATI. VICE PRESIDENT OF INDIA; UP-RASHTRAPATI. SPEAKER, LOK SABHA. CHAIRMAN, RAJYA SABHA. PRIME MINISTER OF INDIA. MINISTER, UNION GOVERNMENT. MEMBER OF PARLIAMENT. | Y3: =IF(COUNTA(E3:J3,P3:W3)=0,"Not started",IF(COUNTA(E3:J3,P3:W3)<14,"Incomplete",IF((AND(F3<>"",F3&""<>"0",TRIM(K3)="")+AND(G3<>"",G3&""<>"0",TRIM(L3)="")+AND(H3<>"",H3&""<>"0",TRIM(M3)="")+AND(I3<>"",I3&""<>"0",TRIM(N3)="")+AND(J3<>"",J3&""<>"0",TRIM(O3)=""))>0,"Add evidence","Complete"))) | Z3: 1111 | AA3: Legislators | AB3: 111 | AC3: Legislators and Senior Officials | AD3: 1 | AE3: Managers | AF3: Not defined | AG3: 1111.10
A4: 2 | B4: 1111.0200 | C4: Elected Official, State Government | D4: Elected Official, State Government serves in various capacities in legislative and executive branches of State Government. Performs, administrative, executive or advisory functions, which include leading council of ministers of State Government; shaping, determining and defining government policies, and directing application and execution of government policies through departmental heads; presiding over deliberations of Houses of State Legislatures; committees and commissions; and taking part in making, amending or repealing laws. Is designated according to work performed or post held, such as: CHIEF MINISTER. MINISTER, STATE GOVERNMENT. CHAIRMAN, LEGISLATIVE COUNCIL. SPEAKER, LEGISLATIVE ASSEMBLY. MEMBER, LEGISLATIVE ASSEMBLY. | Y4: =IF(COUNTA(E4:J4,P4:W4)=0,"Not started",IF(COUNTA(E4:J4,P4:W4)<14,"Incomplete",IF((AND(F4<>"",F4&""<>"0",TRIM(K4)="")+AND(G4<>"",G4&""<>"0",TRIM(L4)="")+AND(H4<>"",H4&""<>"0",TRIM(M4)="")+AND(I4<>"",I4&""<>"0",TRIM(N4)="")+AND(J4<>"",J4&""<>"0",TRIM(O4)=""))>0,"Add evidence","Complete"))) | Z4: 1111 | AA4: Legislators | AB4: 111 | AC4: Legislators and Senior Officials | AD4: 1 | AE4: Managers | AF4: Not defined | AG4: 1112.10
A5: 3 | B5: 1111.0300 | C5: Elected Official, Local Bodies | D5: Elected Official, Local Bodies serves in various capacities in policy making and executive branches of local bodies. Performs administrative, executive or advisory functions in matters entrusted to local bodies e.g. public health, sanitation, primary education, building and road construction, drainage, street-lighting, raising and collection of admissible local taxes and their proper administration, and all other connected matters for the benefit of local people, including enforcement of local laws and emergency measures as necessary. Is designated according to work performed or post held such as: MAYOR, MUNICIPAL CORPORATION. COUNCILLOR, CITY MUNICIPAL CORPORATION. CHAIRMAN, CITY MUNICIPAL CORPORATION. CHAIRMAN, MUNICIPALITY. MEMBER MUNICIPALITY. CHAIRMAN, DISTRICT BOARD. MEMBER, DISTRICT BOARD. CHAIRMAN, CANTONMENT BOARD. MEMBER, CANTONMENT BOARD. CHAIRMAN, TOWN AREA COMMITTEE. MEMBER, TOWN AREA COMMITTEE. CHAIRMAN, BLOCK SAMITI. SARPANCH, PANCHAYAT. MEMBER, PANCHAYAT. | Y5: =IF(COUNTA(E5:J5,P5:W5)=0,"Not started",IF(COUNTA(E5:J5,P5:W5)<14,"Incomplete",IF((AND(F5<>"",F5&""<>"0",TRIM(K5)="")+AND(G5<>"",G5&""<>"0",TRIM(L5)="")+AND(H5<>"",H5&""<>"0",TRIM(M5)="")+AND(I5<>"",I5&""<>"0",TRIM(N5)="")+AND(J5<>"",J5&""<>"0",TRIM(O5)=""))>0,"Add evidence","Complete"))) | Z5: 1111 | AA5: Legislators | AB5: 111 | AC5: Legislators and Senior Officials | AD5: 1 | AE5: Managers | AF5: Not defined | AG5: 1113.10
A6: 4 | B6: 1111.9900 | C6: Legislators, Other | D6: Elected Officials, Other include all other Elected Officials performing administrative, executive or advisory functions in educational, religious, social, political and community welfare organizations and such other permanent or ad-hoc private bodies, not else-where classified. | Y6: =IF(COUNTA(E6:J6,P6:W6)=0,"Not started",IF(COUNTA(E6:J6,P6:W6)<14,"Incomplete",IF((AND(F6<>"",F6&""<>"0",TRIM(K6)="")+AND(G6<>"",G6&""<>"0",TRIM(L6)="")+AND(H6<>"",H6&""<>"0",TRIM(M6)="")+AND(I6<>"",I6&""<>"0",TRIM(N6)="")+AND(J6<>"",J6&""<>"0",TRIM(O6)=""))>0,"Add evidence","Complete"))) | Z6: 1111 | AA6: Legislators | AB6: 111 | AC6: Legislators and Senior Officials | AD6: 1 | AE6: Managers | AF6: Not defined | AG6: 1119.90
A7: 5 | B7: 1112.0100 | C7: Administrative Official, Union Government | D7: Administrative Official, Union Government serves in various capacities under Union Government. Performs administrative and advisory functions, which include advising minister on all matters of policy and administration within his sphere of responsibility; organizing and directing work of ministries and departments; taking policy decisions to extent authorized; supervising execution and implementation of policies and decisions by field or subordinate offices etc. Is designated according to work performed or post held, such as: MEMBER, OF UNION PUBLIC SERVICE COMMISSION. MEMBER, CENTRAL BOARD OF REVENUE. MEMBER, RAILWAY BOARD. MEMBER PLANNING COMMISSION. SECRETARY TO THE GOVERNMENT OF INDIA JOINT SECRETARY TO THE GOVERNMENT OF INDIA. DEPUTY SECRETARY TO THE GOVERNMENT OF INDIA. UNDER SECRETARY TO THE GOVERNMENT OF INDIA. DIRECTOR-GENERAL, CIVIL AVIATION. DIRECTOR GENERAL, ALL INDIA RADIO DIRECTOR-GENERAL, POSTS AND TELEGRAPHS. DIRECTOR-GENERAL, SUPPLIES AND DISPOSALS. DIRECTOR-GENERAL SHIPPING. DIRECTOR-GENERAL OF EMPLOYMENT AND TRAINING. CONTROLLER AND AUDITOR GENERAL. CONTROLLER, IRON AND STEEL. COMMISSIONER, TEXTILE. CUSTODIAN GENERAL. CHIEF CONTROLLER OF IMPORTS AND EXPORTS. CHIEF COMMISSIONER, ELECTION. CHIEF COMMISSIONER, LABOUR COMMISSIONER, SALT. REGISTRAR-GENERAL, CENSUS | Y7: =IF(COUNTA(E7:J7,P7:W7)=0,"Not started",IF(COUNTA(E7:J7,P7:W7)<14,"Incomplete",IF((AND(F7<>"",F7&""<>"0",TRIM(K7)="")+AND(G7<>"",G7&""<>"0",TRIM(L7)="")+AND(H7<>"",H7&""<>"0",TRIM(M7)="")+AND(I7<>"",I7&""<>"0",TRIM(N7)="")+AND(J7<>"",J7&""<>"0",TRIM(O7)=""))>0,"Add evidence","Complete"))) | Z7: 1112 | AA7: Senior Government Officials | AB7: 111 | AC7: Legislators and Senior Officials | AD7: 1 | AE7: Managers | AF7: Not defined | AG7: 1121.10
A8: 6 | B8: 1112.0200 | C8: Diplomat | D8: Diplomat represents Union of India in other countries or at international organizations, meetings and conferences. Interprets policies of Indian Government in foreign countries and advises his Government on matters of foreign relations, trade, commerce, etc. Negotiates and enters into agreements with other countries and nations. Issues visas to foreigners for visit to India and looks after welfare of Indians abroad, and generally promotes interest of his country. Is designated according to rank held or work performed, such as: AMBASSADOR HIGH COMMISSIONER ENVOY MINISTER (DIPLOMAT) PERMANENT REPRESENTATIVE COUNSEL GENERAL CHARGE D AFFAIRS TRADE COMMISSIONER. | Y8: =IF(COUNTA(E8:J8,P8:W8)=0,"Not started",IF(COUNTA(E8:J8,P8:W8)<14,"Incomplete",IF((AND(F8<>"",F8&""<>"0",TRIM(K8)="")+AND(G8<>"",G8&""<>"0",TRIM(L8)="")+AND(H8<>"",H8&""<>"0",TRIM(M8)="")+AND(I8<>"",I8&""<>"0",TRIM(N8)="")+AND(J8<>"",J8&""<>"0",TRIM(O8)=""))>0,"Add evidence","Complete"))) | Z8: 1112 | AA8: Senior Government Officials | AB8: 111 | AC8: Legislators and Senior Officials | AD8: 1 | AE8: Managers | AF8: Not defined | AG8: 1121.20
A9: 7 | B9: 1112.0300 | C9: Executive Officials, Union Government | D9: Executive Official, Union Government serves in various executive capacities in Union Government, giving effect to policies and decisions of Government. Performs or supervises performance of other executives and field duties such as assessing and collecting revenues; issuing passports, licenses and other authorizations; supervising elections; reconciling parties in trade disputes; inspecting offices and establishments; enforcing and implementing various rules, regulations and provisions of law. Is designated according to work performed or post held, such as: COMMISSIONER, DEVELOPMENT COMMISSIONER, INCOME-TAX CUSTODIAN, EVACUEE PROPERTY DIRECTOR OF INSPECTION, CUSTOMS DIRECTOR, MARKETING DIRECTOR OF TRAINING, DIRECTOR OF EMPLOYMENT EXCHANGES, REGIONAL LABOUR COMMISSIONER, COLLECTOR, CENTRAL EXCISE, SUPERINTENDENT, CUSTOMS, INCOME-TAX OFFICER, SUPERINTENDENT, CENTRAL EXCISE, PASSPORT OFFICER, SETTLEMENT OFFICER, CONCILIATION OFFICER (CENTRAL). | Y9: =IF(COUNTA(E9:J9,P9:W9)=0,"Not started",IF(COUNTA(E9:J9,P9:W9)<14,"Incomplete",IF((AND(F9<>"",F9&""<>"0",TRIM(K9)="")+AND(G9<>"",G9&""<>"0",TRIM(L9)="")+AND(H9<>"",H9&""<>"0",TRIM(M9)="")+AND(I9<>"",I9&""<>"0",TRIM(N9)="")+AND(J9<>"",J9&""<>"0",TRIM(O9)=""))>0,"Add evidence","Complete"))) | Z9: 1112 | AA9: Senior Government Officials | AB9: 111 | AC9: Legislators and Senior Officials | AD9: 1 | AE9: Managers | AF9: Not defined | AG9: 1121.30
A10: 8 | B10: 1112.0400 | C10: Administrative Official, State Government | D10: Administrative Official, State Government serves in various capacities in State Government. Performs administrative and advisory functions which include serving as Head of State; advising ministers, on all matters of policy and administration within his sphere of responsibility; organizing and directing work of departments; taking policy decisions to the extent authorised; supervising execution and implementation of policies and decisions by field or subordinate officers. Is designated according to work performed or post held, such as: GOVERNOR; RAJYAPAL; LIEUTENANT GOVERNOR MEMBER, STATE PUBLIC SERVICE COMMISSION, MEMBER, BOARD OF REVENUE, CHIEF SECRETARY TO GOVERNMENT (STATE), SECRETARY TO GOVERNMENT (STATE), DEPUTY SECRETARY TO GOVERNMENT (STATE), UNDER SECRETARY TO GOVERNMENT (STATE), CHIEF COMMISSIONER DEVELOPMENT, COMMISSIONER OF DIVISION, DIRECTOR OF EDUCATION, DIRECTOR OF INDUSTRIES. | Y10: =IF(COUNTA(E10:J10,P10:W10)=0,"Not started",IF(COUNTA(E10:J10,P10:W10)<14,"Incomplete",IF((AND(F10<>"",F10&""<>"0",TRIM(K10)="")+AND(G10<>"",G10&""<>"0",TRIM(L10)="")+AND(H10<>"",H10&""<>"0",TRIM(M10)="")+AND(I10<>"",I10&""<>"0",TRIM(N10)="")+AND(J10<>"",J10&""<>"0",TRIM(O10)=""))>0,"Add evidence","Complete"))) | Z10: 1112 | AA10: Senior Government Officials | AB10: 111 | AC10: Legislators and Senior Officials | AD10: 1 | AE10: Managers | AF10: Not defined | AG10: 1122.10
A11: 9 | B11: 1112.0500 | C11: Executive Official, State Government | D11: Executive Official, State Government serves in various capacities in State Government giving effect to policies and decisions of Government. Performs or supervises performance of executive and field duties which include maintenance of law and order; assessing and collecting taxes, duties, land revenues, etc.; issuing licenses; executing development schemes; reconciling parties in trade disputes; inspecting schools, factories, shops, offices and establishments; and enforcing various rules, regulations and provisions of law. Is designated according to work performed or post held, such as: COLLECTOR; DEPUTY COLLECTOR; SUB-DEPUTY COLLECTOR; DEPUTY COMMISSIONER. DISTRICT OFFICER; SUB-DIVISIONAL OFFICER; LAND RECORD OFFICER; TEHSILDAR; SUPERINTENDENT OF POLICE CIRCLE OFFICE; SALES-TAX OFFICER; SUPERINTENDENT, JAIL; JAILOR, SUPERINTENDENT OF INDUSTRIES DISTRICT INDUSTRIES OFFICER MARKETING OFFICER. RATIONING OFFICER. SUPPLY OFFICER. RENT CONTROL AND EVICTION OFFICER, REGIONAL TRANSPORT OFFICER, DISTRICT PLANNING OFFICER, CO-OPERATIVE OFFICER, CONCILIATION OFFICER (STATE), PANCHAYAT RAJ OFFICER. | Y11: =IF(COUNTA(E11:J11,P11:W11)=0,"Not started",IF(COUNTA(E11:J11,P11:W11)<14,"Incomplete",IF((AND(F11<>"",F11&""<>"0",TRIM(K11)="")+AND(G11<>"",G11&""<>"0",TRIM(L11)="")+AND(H11<>"",H11&""<>"0",TRIM(M11)="")+AND(I11<>"",I11&""<>"0",TRIM(N11)="")+AND(J11<>"",J11&""<>"0",TRIM(O11)=""))>0,"Add evidence","Complete"))) | Z11: 1112 | AA11: Senior Government Officials | AB11: 111 | AC11: Legislators and Senior Officials | AD11: 1 | AE11: Managers | AF11: Not defined | AG11: 1122.20
A12: 10 | B12: 1112.0600 | C12: Administrative and Executive Officials, Quasi Government (Central) | D12: Administrative and Executive Official, Quasi Government (Central) plans, organizes, co-ordinates and controls within authority delegated, activities of quasi-government organizations, establishment, etc. or one or more of its departments/branches or sections; and includes officials such as: CHAIRMAN, UNIVERSITY GRANTS COMMISSION CHAIRMAN, COAL MINES WELFARE COMMISSION, SECRETARY, INDIAN RED CROSS SOCIETY, SECRETARY, MICA MINES LABOUR WELFARE FUND ADVISORY COMMITTEE, SECRETARY, RAILWAY RATES TRIBUNAL, CONTROLLER OF EMIGRANT LABOUR, DIRECTOR-GENERAL, EMPLOYEES STATE INSURANCE CORPORATION. | Y12: =IF(COUNTA(E12:J12,P12:W12)=0,"Not started",IF(COUNTA(E12:J12,P12:W12)<14,"Incomplete",IF((AND(F12<>"",F12&""<>"0",TRIM(K12)="")+AND(G12<>"",G12&""<>"0",TRIM(L12)="")+AND(H12<>"",H12&""<>"0",TRIM(M12)="")+AND(I12<>"",I12&""<>"0",TRIM(N12)="")+AND(J12<>"",J12&""<>"0",TRIM(O12)=""))>0,"Add evidence","Complete"))) | Z12: 1112 | AA12: Senior Government Officials | AB12: 111 | AC12: Legislators and Senior Officials | AD12: 1 | AE12: Managers | AF12: Not defined | AG12: 1123.10
A13: 11 | B13: 1112.0700 | C13: Administrative & Executive Officials, Quasi Government (State) | D13: Administrative and Executive Official, Quasi Government (State) plans, organizes, co-ordinates and controls within authority delegated, activities of quasi-government organizations, establishments, etc. or one or more of its departments/branches or sections; and includes officials such as: VICE CHANCELLOR, STATE UNIVERSITIES, DEAN, STATE AUTONOMOUS EDUCATIONAL INSTITUTES, CHAIRMAN, STATE CORPORATIONS/BOARDS, CHAIRMAN, HARYANA URBAN DEVELOPMENT AUTHORITY, SECRETARY, GHAZIABAD DEVELOPMENT AUTHORITY. | Y13: =IF(COUNTA(E13:J13,P13:W13)=0,"Not started",IF(COUNTA(E13:J13,P13:W13)<14,"Incomplete",IF((AND(F13<>"",F13&""<>"0",TRIM(K13)="")+AND(G13<>"",G13&""<>"0",TRIM(L13)="")+AND(H13<>"",H13&""<>"0",TRIM(M13)="")+AND(I13<>"",I13&""<>"0",TRIM(N13)="")+AND(J13<>"",J13&""<>"0",TRIM(O13)=""))>0,"Add evidence","Complete"))) | Z13: 1112 | AA13: Senior Government Officials | AB13: 111 | AC13: Legislators and Senior Officials | AD13: 1 | AE13: Managers | AF13: Not defined | AG13: 1123.20
A14: 12 | B14: 1112.0800 | C14: Administrative and Executive Officials, Local Bodies | D14: Administrative and Executive Official, Local Bodies plans, organizes, co-ordinates and controls functions of the city corporation, improvement trust, municipality, district board, cantonment board, notified area committee or other local bodies, and executes and implements or supervises execution and implementation of decisions, rules and regulations and by-laws of local bodies and also assesses and collects local taxes. Is designated according to work performed or post held, such as: COMMISSIONER, CITY CORPORATION, EXECUTIVE OFFICER, IMPROVEMENT TRUST; EXECUTIVE OFFICER, CANTONMENT, BOARD; EXECUTIVE OFFICER; MUNICIPAL BOARD, SECRETARY, DISTRICT BOARD TAX SUPERINTENDENT, OCTROI SUPERINTENDENT | Y14: =IF(COUNTA(E14:J14,P14:W14)=0,"Not started",IF(COUNTA(E14:J14,P14:W14)<14,"Incomplete",IF((AND(F14<>"",F14&""<>"0",TRIM(K14)="")+AND(G14<>"",G14&""<>"0",TRIM(L14)="")+AND(H14<>"",H14&""<>"0",TRIM(M14)="")+AND(I14<>"",I14&""<>"0",TRIM(N14)="")+AND(J14<>"",J14&""<>"0",TRIM(O14)=""))>0,"Add evidence","Complete"))) | Z14: 1112 | AA14: Senior Government Officials | AB14: 111 | AC14: Legislators and Senior Officials | AD14: 1 | AE14: Managers | AF14: Not defined | AG14: 1124.10
... A37: 35 | B37: 1120.1800 | C37: Director Manufacturing | D37: Director, Manufacturing plans, organizes, co-ordinates and controls within authority delegated, activities of private or public organizations, or one or more of its departments or branches, engaged in producing, maintaining or repairing capital or consumer goods, excluding crops, minerals, electricity and natural gas. Is designated according to work performed, authority exercised or economic activity directed such as: MANAGING DIRECTOR, (MANUFACTURING). DIRECTOR, PRODUCTION(MANUFACTURING). DIRECTOR, WORKS(MANUFACTURING). DIRECTOR, STEEL PLANT. DIRECTOR, TANNERY. DIRECTOR, BAKERY. DIRECTOR, SADDLERY. | Y37: =IF(COUNTA(E37:J37,P37:W37)=0,"Not started",IF(COUNTA(E37:J37,P37:W37)<14,"Incomplete",IF((AND(F37<>"",F37&""<>"0",TRIM(K37)="")+AND(G37<>"",G37&""<>"0",TRIM(L37)="")+AND(H37<>"",H37&""<>"0",TRIM(M37)="")+AND(I37<>"",I37&""<>"0",TRIM(N37)="")+AND(J37<>"",J37&""<>"0",TRIM(O37)=""))>0,"Add evidence","Complete"))) | Z37: 1120 | AA37: Managing Directors and Chief Executives | AB37: 112 | AC37: Managing Directors and Chief Executives | AD37: 1 | AE37: Managers | AF37: Not defined | AG37: 1214.20
A38: 36 | B38: 1120.1900 | C38: Working Proprietor, Wholesale Trade/Proprietor, Wholesale Trade | D38: Working Proprietor, Wholesale Trade purchases goods in bulk and sells them to retailers or other large consumers for profit. Lays down and controls business policies to ensure profits, keeping in view price line, market trend and demand and supply position. Appoints Directors, Managers and Representatives and delegates financial and operational powers to them, if necessary. Runs wholesale trade on monopoly or zonal basis in specific commodities either by importing them from outside or manufacturing them in his own or other concern. May require a licence or permit from public authorities for wholesale trade. May undertake export business. | Y38: =IF(COUNTA(E38:J38,P38:W38)=0,"Not started",IF(COUNTA(E38:J38,P38:W38)<14,"Incomplete",IF((AND(F38<>"",F38&""<>"0",TRIM(K38)="")+AND(G38<>"",G38&""<>"0",TRIM(L38)="")+AND(H38<>"",H38&""<>"0",TRIM(M38)="")+AND(I38<>"",I38&""<>"0",TRIM(N38)="")+AND(J38<>"",J38&""<>"0",TRIM(O38)=""))>0,"Add evidence","Complete"))) | Z38: 1120 | AA38: Managing Directors and Chief Executives | AB38: 112 | AC38: Managing Directors and Chief Executives | AD38: 1 | AE38: Managers | AF38: Not defined
A39: 37 | B39: 1120.2000 | C39: Working Proprietor, Retail Trade/Proprietor, Retail Trade | D39: Working Proprietor, Retail Trade conducts business in retail trade on own account, buying merchandise from manufacturers or wholesalers according to public demand and sells them to customers for profit. Lays down business policies regarding margin of profit and compliance with prescribed rules and regulations. May appoint Directors and Managers and may delegate financial and operational powers to them. May obtain licence or permit from public authorities for retail trade. | Y39: =IF(COUNTA(E39:J39,P39:W39)=0,"Not started",IF(COUNTA(E39:J39,P39:W39)<14,"Incomplete",IF((AND(F39<>"",F39&""<>"0",TRIM(K39)="")+AND(G39<>"",G39&""<>"0",TRIM(L39)="")+AND(H39<>"",H39&""<>"0",TRIM(M39)="")+AND(I39<>"",I39&""<>"0",TRIM(N39)="")+AND(J39<>"",J39&""<>"0",TRIM(O39)=""))>0,"Add evidence","Complete"))) | Z39: 1120 | AA39: Managing Directors and Chief Executives | AB39: 112 | AC39: Managing Directors and Chief Executives | AD39: 1 | AE39: Managers | AF39: Not defined | AG39: 1214.40
A40: 38 | B40: 1120.2100 | C40: Director, Wholesale Trade | D40: Director, Wholesale Trade lays down policies within powers ,delegated, and plans, controls and directs operation of private or public enterprise or segment of its activities engaged in buying and selling of goods in wholesale. Is designated according to work performed, such as: MANAGING DIRECTOR (Wholesale Trade). CHAIRMAN, BOARD OF DIRECTORS (Wholesale Trade). | Y40: =IF(COUNTA(E40:J40,P40:W40)=0,"Not started",IF(COUNTA(E40:J40,P40:W40)<14,"Incomplete",IF((AND(F40<>"",F40&""<>"0",TRIM(K40)="")+AND(G40<>"",G40&""<>"0",TRIM(L40)="")+AND(H40<>"",H40&""<>"0",TRIM(M40)="")+AND(I40<>"",I40&""<>"0",TRIM(N40)="")+AND(J40<>"",J40&""<>"0",TRIM(O40)=""))>0,"Add evidence","Complete"))) | Z40: 1120 | AA40: Managing Directors and Chief Executives | AB40: 112 | AC40: Managing Directors and Chief Executives | AD40: 1 | AE40: Managers | AF40: Not defined | AG40: 1214.50
A41: 39 | B41: 1120.2200 | C41: Director, Retail Trade | D41: Director, Retail Trade lays down policies within powers delegated and plans, controls and directs operation of private or public enterprises or a segment of its activities, engaged in buying and selling goods in retail. Is designated according to work performed such as: MANAGING DIRECTOR (Retail Trade), CHAIRMAN, BOARD OF DIRECTORS (Retail Trade) DIRECTOR-IN-CHARGE (Retail Trade). | Y41: =IF(COUNTA(E41:J41,P41:W41)=0,"Not started",IF(COUNTA(E41:J41,P41:W41)<14,"Incomplete",IF((AND(F41<>"",F41&""<>"0",TRIM(K41)="")+AND(G41<>"",G41&""<>"0",TRIM(L41)="")+AND(H41<>"",H41&""<>"0",TRIM(M41)="")+AND(I41<>"",I41&""<>"0",TRIM(N41)="")+AND(J41<>"",J41&""<>"0",TRIM(O41)=""))>0,"Add evidence","Complete"))) | Z41: 1120 | AA41: Managing Directors and Chief Executives | AB41: 112 | AC41: Managing Directors and Chief Executives | AD41: 1 | AE41: Managers | AF41: Not defined | AG41: 1214.60
A42: 40 | B42: 1120.2300 | C42: Working Proprietor, Transport | D42: Working Proprietor, Transport plans, organizes, co-ordinates and controls activities of the organization or establishment wholly or partly owned by him, is engaged in transporting passengers and freight by buses, trucks, taxis, rickshaws, tongas, and other means of road transport; by boats, launches, ships, etc. plying on inland or coastal waters or on high seas; by aircraft for providing transport and other services, incidental to transport. | Y42: =IF(COUNTA(E42:J42,P42:W42)=0,"Not started",IF(COUNTA(E42:J42,P42:W42)<14,"Incomplete",IF((AND(F42<>"",F42&""<>"0",TRIM(K42)="")+AND(G42<>"",G42&""<>"0",TRIM(L42)="")+AND(H42<>"",H42&""<>"0",TRIM(M42)="")+AND(I42<>"",I42&""<>"0",TRIM(N42)="")+AND(J42<>"",J42&""<>"0",TRIM(O42)=""))>0,"Add evidence","Complete"))) | Z42: 1120 | AA42: Managing Directors and Chief Executives | AB42: 112 | AC42: Managing Directors and Chief Executives | AD42: 1 | AE42: Managers | AF42: Not defined | AG42: 1215.10
A43: 41 | B43: 1120.2400 | C43: Director, Transport | D43: Director, Transport plans organizes, co-ordinates and controls, within authority delegated, activities of private or public organizations or one or more of its departments, branches or sections, engaged in transporting passengers and freight by railways, tramways, buses, trucks, taxis, rickshaws, animal transport and other means of road transport; by boats, launches and ships plying on rivers, coastal waters, and high seas; by aircrafts; and operating services incidental to transport. Is designated according to work performed, powers exercised of service controlled, such as: MANAGING DIRECTOR (TRANSPORT). DIRECTOR, TRAFFIC GENERAL, MANAGER, RAILWAYS, DIRECTOR, ROADWAYS, CHIEF OPERATING SUPERINTENDENT(RAILWAYS). CHIEF COMMERCIAL SUPERINTENDENT(RAILWAYS). | Y43: =IF(COUNTA(E43:J43,P43:W43)=0,"Not started",IF(COUNTA(E43:J43,P43:W43)<14,"Incomplete",IF((AND(F43<>"",F43&""<>"0",TRIM(K43)="")+AND(G43<>"",G43&""<>"0",TRIM(L43)="")+AND(H43<>"",H43&""<>"0",TRIM(M43)="")+AND(I43<>"",I43&""<>"0",TRIM(N43)="")+AND(J43<>"",J43&""<>"0",TRIM(O43)=""))>0,"Add evidence","Complete"))) | Z43: 1120 | AA43: Managing Directors and Chief Executives | AB43: 112 | AC43: Managing Directors and Chief Executives | AD43: 1 | AE43: Managers | AF43: Not defined | AG43: 1215.20
A44: 42 | B44: 1120.2500 | C44: Director, Communication | D44: Director, Communication plans, organizes, co-ordinates and controls, within authority delegated, activities of public or private organization or one or more of its departments or branches, engaged in providing postal, telephone, telegraph, wireless and other communication services. Is designated according to powers exercised or type of communication service directed such as: DIRECTOR, POSTAL SERVICES, POST MASTER GENERAL. DIRECTOR, OVERSEAS COMMUNICATION SERVICES. DIRECTOR OF TELEPHONES, DIRECTOR OF RAILWAY MAIL SERVICE. | Y44: =IF(COUNTA(E44:J44,P44:W44)=0,"Not started",IF(COUNTA(E44:J44,P44:W44)<14,"Incomplete",IF((AND(F44<>"",F44&""<>"0",TRIM(K44)="")+AND(G44<>"",G44&""<>"0",TRIM(L44)="")+AND(H44<>"",H44&""<>"0",TRIM(M44)="")+AND(I44<>"",I44&""<>"0",TRIM(N44)="")+AND(J44<>"",J44&""<>"0",TRIM(O44)=""))>0,"Add evidence","Complete"))) | Z44: 1120 | AA44: Managing Directors and Chief Executives | AB44: 112 | AC44: Managing Directors and Chief Executives | AD44: 1 | AE44: Managers | AF44: Not defined | AG44: 1215.30
A45: 43 | B45: 1120.2600 | C45: Director, Airport | D45: Director, Airport plans, directs, and co-ordinates, through subordinate personnel, activities concerned with construction and maintenance of airport facilities and operation of airport in accordance with governmental agencies or commission policies and regulations. Consults with commission members, governmental officials, or representatives of airlines to discuss and plan matters, such as design and development of airport facilities, formulation of operating rules, regulations, and procedures, and aircraft landing, taxiing, and take-off patterns for various types of aircrafts. Negotiates with representatives of airlines, utility companies, or individuals for acquisition of property for development of airports, lease of airport buildings and facilities, or use of rights-of-way over private property. Formulates procedures for use in event of aircraft accidents, fires, or other emergencies. Inspects airport facilities, such as runways, buildings, beacons and lighting, and automotive or construction equipment, or reviews inspection reports, to determine repairs, replacement, or improvements required. Co-ordinates activities of personnel involved in repair and maintenance of airport facilities, buildings, and equipment to minimize interruption of airport operations and improve efficiency. Directs personnel in investigating violations of aerial or ground traffic regulations, reviews investigation reports, and initiates actions to be taken against violators. Directs studies on noise abatement resulting from complaints of excessive noise from low flying aircraft or other operations. Reviews reports of expenditures for previous fiscal year, proposes improvements to facilitate, estimated increase in volume of traffic, in order to prepare budget estimates for upcoming fiscal year. Represents airport before civic or other organizational groups, courts, boards, and commissions. | Y45: =IF(COUNTA(E45:J45,P45:W45)=0,"Not started",IF(COUNTA(E45:J45,P45:W45)<14,"Incomplete",IF((AND(F45<>"",F45&""<>"0",TRIM(K45)="")+AND(G45<>"",G45&""<>"0",TRIM(L45)="")+AND(H45<>"",H45&""<>"0",TRIM(M45)="")+AND(I45<>"",I45&""<>"0",TRIM(N45)="")+AND(J45<>"",J45&""<>"0",TRIM(O45)=""))>0,"Add evidence","Complete"))) | Z45: 1120 | AA45: Managing Directors and Chief Executives | AB45: 112 | AC45: Managing Directors and Chief Executives | AD45: 1 | AE45: Managers | AF45: Not defined | AG45: 1215.40
A46: 44 | B46: 1120.2700 | C46: Working Proprietor, Storage and Warehousing | D46: Working Proprietor, Storage and Warehousing plans and organizes storage warehousing and freight handling services to public and private organizations by land, sea or air and arranges allied transport and communication facilities to parties concerned. Obtains license from Government where necessary, and lays down business policies. Appoints Directors, Agents and Managers and delegates required financial and other powers to them to ensure smooth running of business, desired margin of profit and compliance with business terms and Government rules and regulations. | Y46: =IF(COUNTA(E46:J46,P46:W46)=0,"Not started",IF(COUNTA(E46:J46,P46:W46)<14,"Incomplete",IF((AND(F46<>"",F46&""<>"0",TRIM(K46)="")+AND(G46<>"",G46&""<>"0",TRIM(L46)="")+AND(H46<>"",H46&""<>"0",TRIM(M46)="")+AND(I46<>"",I46&""<>"0",TRIM(N46)="")+AND(J46<>"",J46&""<>"0",TRIM(O46)=""))>0,"Add evidence","Complete"))) | Z46: 1120 | AA46: Managing Directors and Chief Executives | AB46: 112 | AC46: Managing Directors and Chief Executives | AD46: 1 | AE46: Managers | AF46: Not defined | AG46: 1216.10
A47: 45 | B47: 1120.2800 | C47: Director, Storage and Warehousing | D47: Director, Storage and Warehousing plans, organizes, co-ordinates and controls, within authority delegated, activities of public or private organizations, or one or more of its branches, engaged in providing storage and warehouse facilities on prescribed terms and conditions to Government and private parties. May arrange facilities of transport and communication as required. May specialize in any particular type of item or commodity such as machinery and engineering items, explosives, perishable goods, etc. and be designated accordingly. | Y47: =IF(COUNTA(E47:J47,P47:W47)=0,"Not started",IF(COUNTA(E47:J47,P47:W47)<14,"Incomplete",IF((AND(F47<>"",F47&""<>"0",TRIM(K47)="")+AND(G47<>"",G47&""<>"0",TRIM(L47)="")+AND(H47<>"",H47&""<>"0",TRIM(M47)="")+AND(I47<>"",I47&""<>"0",TRIM(N47)="")+AND(J47<>"",J47&""<>"0",TRIM(O47)=""))>0,"Add evidence","Complete"))) | Z47: 1120 | AA47: Managing Directors and Chief Executives | AB47: 112 | AC47: Managing Directors and Chief Executives | AD47: 1 | AE47: Managers | AF47: Not defined | AG47: 1216.20
A48: 46 | B48: 1120.2900 | C48: Working Proprietor, Lodging and Catering Services | D48: Working Proprietor, Lodging and Catering Services plans, organizes, co-ordinates and controls operations of the organization or establishment wholly or partly owned by him and is engaged in serving food, drinks and beverages and providing lodging and camping facilities to public. Included are: WORKING PROPRIETOR, HOTEL. WORKING PROPRIETOR, RESTAURANT. WORKING PROPRIETOR, CAFE WORKING PROPRIETOR, COFFEE HOUSE. | Y48: =IF(COUNTA(E48:J48,P48:W48)=0,"Not started",IF(COUNTA(E48:J48,P48:W48)<14,"Incomplete",IF((AND(F48<>"",F48&""<>"0",TRIM(K48)="")+AND(G48<>"",G48&""<>"0",TRIM(L48)="")+AND(H48<>"",H48&""<>"0",TRIM(M48)="")+AND(I48<>"",I48&""<>"0",TRIM(N48)="")+AND(J48<>"",J48&""<>"0",TRIM(O48)=""))>0,"Add evidence","Complete"))) | Z48: 1120 | AA48: Managing Directors and Chief Executives | AB48: 112 | AC48: Managing Directors and Chief Executives | AD48: 1 | AE48: Managers | AF48: Not defined | AG48: 1217.10
A49: 47 | B49: 1120.3000 | C49: Director, Lodging and Catering Services/Director Food and Beverage Service | D49: Director, Lodging and Catering Services plans, organizes and controls, within authority delegated, activities of public or private organizations or establishments or one or more of its branches, engaged in preparing and serving food, drinks and beverages and providing lodging, and camping facilities to public. Included are: DIRECTOR, HOTEL. DIRECTOR, RESTAURANT. DIRECTOR, COFFEE HOUSE | Y49: =IF(COUNTA(E49:J49,P49:W49)=0,"Not started",IF(COUNTA(E49:J49,P49:W49)<14,"Incomplete",IF((AND(F49<>"",F49&""<>"0",TRIM(K49)="")+AND(G49<>"",G49&""<>"0",TRIM(L49)="")+AND(H49<>"",H49&""<>"0",TRIM(M49)="")+AND(I49<>"",I49&""<>"0",TRIM(N49)="")+AND(J49<>"",J49&""<>"0",TRIM(O49)=""))>0,"Add evidence","Complete"))) | Z49: 1120 | AA49: Managing Directors and Chief Executives | AB49: 112 | AC49: Managing Directors and Chief Executives | AD49: 1 | AE49: Managers | AF49: Not defined | AG49: 1217.20
A50: 48 | B50: 1120.3100 | C50: Executive Chef | D50: Executive Chef co-ordinates activities and directs indoctrination and training of CHEFS, COOKS; and other kitchen workers engaged in preparing and cooking food in hotels or restaurants to ensure an efficient and profitable food service. Plans or participates in planning menus and utilisation of food surpluses and leftovers, taking into account probable number of guests, marketing conditions, popularity of various dishes, and decency of menu. Estimates food consumption and purchase or requisition of foodstuff and kitchen supplies. Reviews menus, analyses recipes, determines food, labour, and overhead costs, and assigns price to menu items. Directs food apportionment policy to control costs. Supervises cooking and other kitchen personnel and co-ordinates their assignments to ensure economical and timely food production. Observes methods of food preparation and cooking, size of portions, and garnishing of food to ensure food is prepared in prescribed manner. Tests cooked food by tasting and smelling them. Devises special dishes and develops recipes. Hires and discharges employees. Familiarizes newly hired CHEFS and COOKS with practices of the restaurant kitchen and oversees training of COOK APPRENTICES. Maintains time and payroll records. Establishes and enforces nutrition and sanitation standards for the restaurant. May supervise or co-operate with STEWARD/STEWARDESS in matters pertaining to kitchen, pantry, and storeroom. | Y50: =IF(COUNTA(E50:J50,P50:W50)=0,"Not started",IF(COUNTA(E50:J50,P50:W50)<14,"Incomplete",IF((AND(F50<>"",F50&""<>"0",TRIM(K50)="")+AND(G50<>"",G50&""<>"0",TRIM(L50)="")+AND(H50<>"",H50&""<>"0",TRIM(M50)="")+AND(I50<>"",I50&""<>"0",TRIM(N50)="")+AND(J50<>"",J50&""<>"0",TRIM(O50)=""))>0,"Add evidence","Complete"))) | Z50: 1120 | AA50: Managing Directors and Chief Executives | AB50: 112 | AC50: Managing Directors and Chief Executives | AD50: 1 | AE50: Managers | AF50: Not defined | AG50: 1217.30
... A53: 51 | B53: 1120.3400 | C53: Station Director, Radio/TV | D53: Station Director, Radio/TV directs and co-ordinates activities of radio or television station, or of cable television franchise. Supervises directly, or through subordinates, personnel engaged in departments, such as sales, programme or engineering. Observes activities to ensure compliance with government regulations. Discusses plans with the marketing personnel to promote sales of programmes and time periods to advertisers and their agencies. Confers with owners or company senior management to discuss station policies and administrative procedures. May prepare operational budget and monitor expenses for station or franchise. May negotiate with motion picture companies for purchase of independent film programmes. May negotiate cable franchise contract with local issuing authority. May develop strategies to promote sales of new cable television service or upgraded service to customers within the franchise area. May contact prospective buyers of station time to promote sale of station services. May manage stations engaged in transmitting broadcasts to foreign countries and be known as Director, International Broadcasting (radio-television broadcast). May perform different duties and responsibilities, according to station size and network affiliation. | Y53: =IF(COUNTA(E53:J53,P53:W53)=0,"Not started",IF(COUNTA(E53:J53,P53:W53)<14,"Incomplete",IF((AND(F53<>"",F53&""<>"0",TRIM(K53)="")+AND(G53<>"",G53&""<>"0",TRIM(L53)="")+AND(H53<>"",H53&""<>"0",TRIM(M53)="")+AND(I53<>"",I53&""<>"0",TRIM(N53)="")+AND(J53<>"",J53&""<>"0",TRIM(O53)=""))>0,"Add evidence","Complete"))) | Z53: 1120 | AA53: Managing Directors and Chief Executives | AB53: 112 | AC53: Managing Directors and Chief Executives | AD53: 1 | AE53: Managers | AF53: Not defined | AG53: 1218.30
A54: 52 | B54: 1120.3401 | C54: Account Director (Advertising Agency) | D54: Account Director (Advertising Agency) is responsible for managing the clients’ advertisement portfolio. | Y54: =IF(COUNTA(E54:J54,P54:W54)=0,"Not started",IF(COUNTA(E54:J54,P54:W54)<14,"Incomplete",IF((AND(F54<>"",F54&""<>"0",TRIM(K54)="")+AND(G54<>"",G54&""<>"0",TRIM(L54)="")+AND(H54<>"",H54&""<>"0",TRIM(M54)="")+AND(I54<>"",I54&""<>"0",TRIM(N54)="")+AND(J54<>"",J54&""<>"0",TRIM(O54)=""))>0,"Add evidence","Complete"))) | Z54: 1120 | AA54: Managing Directors and Chief Executives | AB54: 112 | AC54: Managing Directors and Chief Executives | AD54: 1 | AE54: Managers | AF54: Not defined | AH54: MES/Q0207
A55: 53 | B55: 1120.3402 | C55: Sales Director (Media Org) | D55: Sales Director (Media Org) is responsible for leading the sales efforts of a media and entertainment company. | Y55: =IF(COUNTA(E55:J55,P55:W55)=0,"Not started",IF(COUNTA(E55:J55,P55:W55)<14,"Incomplete",IF((AND(F55<>"",F55&""<>"0",TRIM(K55)="")+AND(G55<>"",G55&""<>"0",TRIM(L55)="")+AND(H55<>"",H55&""<>"0",TRIM(M55)="")+AND(I55<>"",I55&""<>"0",TRIM(N55)="")+AND(J55<>"",J55&""<>"0",TRIM(O55)=""))>0,"Add evidence","Complete"))) | Z55: 1120 | AA55: Managing Directors and Chief Executives | AB55: 112 | AC55: Managing Directors and Chief Executives | AD55: 1 | AE55: Managers | AF55: Not defined | AH55: MES/Q0201
A56: 54 | B56: 1120.3500 | C56: Working Proprietor, Other Services | D56: Working Proprietor, Other Services plans, organizes, co-ordinates and controls activities of the organization, wholly or partly owned by him, and is engaged in running and managing educational institutions; rendering medical and other health services, sanitation, washing and cleaning households, garments, etc. and providing other services. | Y56: =IF(COUNTA(E56:J56,P56:W56)=0,"Not started",IF(COUNTA(E56:J56,P56:W56)<14,"Incomplete",IF((AND(F56<>"",F56&""<>"0",TRIM(K56)="")+AND(G56<>"",G56&""<>"0",TRIM(L56)="")+AND(H56<>"",H56&""<>"0",TRIM(M56)="")+AND(I56<>"",I56&""<>"0",TRIM(N56)="")+AND(J56<>"",J56&""<>"0",TRIM(O56)=""))>0,"Add evidence","Complete"))) | Z56: 1120 | AA56: Managing Directors and Chief Executives | AB56: 112 | AC56: Managing Directors and Chief Executives | AD56: 1 | AE56: Managers | AF56: Not defined | AG56: 1219.10
A57: 55 | B57: 1120.3600 | C57: Director, Other Services | D57: Director, Other Services plans, organizes and controls, within authority delegated, activities of public or private organizations or establishments, or one or more of its departments or branches, engaged in running educational institutions; rendering medical sanitation and other health services. Organizing and providing religious services, promoting welfare of workers or community, giving charity assistance or aid to infirm or orphans. Organizing and managing trade and labour organizations and other civic and social associations, washing and cleaning garments etc., undertaking and cremating; and performing other services. Included are: DIRECTOR OF EDUCATIONAL INSTITUTIONS. DIRECTOR OF CHARITABLE INSTITUTIONS, DIRECTOR, ORPHANAGE DIRECTOR, Y.M.C.A, DIRECTOR, Y.W.C.A. | Y57: =IF(COUNTA(E57:J57,P57:W57)=0,"Not started",IF(COUNTA(E57:J57,P57:W57)<14,"Incomplete",IF((AND(F57<>"",F57&""<>"0",TRIM(K57)="")+AND(G57<>"",G57&""<>"0",TRIM(L57)="")+AND(H57<>"",H57&""<>"0",TRIM(M57)="")+AND(I57<>"",I57&""<>"0",TRIM(N57)="")+AND(J57<>"",J57&""<>"0",TRIM(O57)=""))>0,"Add evidence","Complete"))) | Z57: 1120 | AA57: Managing Directors and Chief Executives | AB57: 112 | AC57: Managing Directors and Chief Executives | AD57: 1 | AE57: Managers | AF57: Not defined | AG57: 1219.20
A58: 56 | B58: 1120.3700 | C58: Director, Museum/Zoo | D58: Director, Museum/Zoo administers affairs of museum, zoo, or similar establishments. Confers with the institution's board of Directors to formulate policies and plan overall operations. Directs acquisition, education, research, public service, and developmental activities of the institution, consulting with curatorial, administrative, and maintenance staff members to implement policies and initiate programmes. Works with members of curatorial and administrative staffs to acquire additions to collections. Confers with administrative staff members to determine budget requirements, plans fund raising drives, prepares applications for grants from government agencies or private foundations, and solicits financial support for institutions. Establishes and maintains contact with administrators of other institutions to exchange information concerning operations and plan, co-ordinate, or consolidate community service and education programmes. Represents the institution at professional and civic social events, conventions, and other gatherings to strengthen relationships with cultural and civic leaders, present lectures or participate in seminars, or explain institution's functions and seek financial support for projects. Reviews materials prepared by staff members, such as articles for journals, requests for grants and reports on institutional programmes, and approves materials or suggests changes. Instructs classes in institution's education programme or as guest lecturer at the university. Writes articles for technical journals or other publications. | Y58: =IF(COUNTA(E58:J58,P58:W58)=0,"Not started",IF(COUNTA(E58:J58,P58:W58)<14,"Incomplete",IF((AND(F58<>"",F58&""<>"0",TRIM(K58)="")+AND(G58<>"",G58&""<>"0",TRIM(L58)="")+AND(H58<>"",H58&""<>"0",TRIM(M58)="")+AND(I58<>"",I58&""<>"0",TRIM(N58)="")+AND(J58<>"",J58&""<>"0",TRIM(O58)=""))>0,"Add evidence","Complete"))) | Z58: 1120 | AA58: Managing Directors and Chief Executives | AB58: 112 | AC58: Managing Directors and Chief Executives | AD58: 1 | AE58: Managers | AF58: Not defined | AG58: 1219.30
A59: 57 | B59: 1120.3800 | C59: Chief Librarian | D59: Chief Librarian plans and administers programme of library services: Submits recommendations on library policies and services to the governing body, such as board of Directors or board of Trustees, and implements policy decisions. Analyses, selects, and executes recommendations of personnel, such as department chiefs or branch supervisors. Co-ordinates activities of the branch or departmental libraries. Analyses and co-ordinates departmental budget estimates and controls expenditures to administer approved budget. Reviews and evaluates orders for books and audio-visual materials. Examines trade publications and materials, interviews publishers' representatives, and consults with others to select materials. Administers personnel regulations, interviews and appoints job applicants and promotes and discharges employees. Plans and conducts staff meetings and participates in community and professional meetings to discuss and act on library problems. Delivers book reviews and lectures to publicise library activities and services. Provides library public relation services. May examine and select materials to be discarded, repaired, or replaced. | Y59: =IF(COUNTA(E59:J59,P59:W59)=0,"Not started",IF(COUNTA(E59:J59,P59:W59)<14,"Incomplete",IF((AND(F59<>"",F59&""<>"0",TRIM(K59)="")+AND(G59<>"",G59&""<>"0",TRIM(L59)="")+AND(H59<>"",H59&""<>"0",TRIM(M59)="")+AND(I59<>"",I59&""<>"0",TRIM(N59)="")+AND(J59<>"",J59&""<>"0",TRIM(O59)=""))>0,"Add evidence","Complete"))) | Z59: 1120 | AA59: Managing Directors and Chief Executives | AB59: 112 | AC59: Managing Directors and Chief Executives | AD59: 1 | AE59: Managers | AF59: Not defined | AG59: 1219.40
A60: 58 | B60: 1120.3900 | C60: Principal, College | D60: Principal College directs and co-ordinates educational, administrative, and counselling activities of college. Develops and evaluates educational programmes to ensure conformance to state and university standards. Develops and co-ordinates educational programmes through meetings with staff, review of teachers' activities, and issuance of directives. Confers with teachers, students, and parents concerning educational and behavioural problems in the college. Establishes and maintains relationships with colleges, community organizations, and other colleges to co-ordinate educational, sports and cultural services. Forwards requisitions and allocates supplies, equipment, and instructional material as needed. Directs preparation of class schedules, cumulative records, and attendance reports. Observes and evaluates teacher’s performance. Interviews and hires teachers. Walks around the college building and property to monitor safety and security. Plans and monitors college budget and financial matters. May plan and direct building maintenance. May develop and administer educational programmes for students with mental or physical handicaps. | Y60: =IF(COUNTA(E60:J60,P60:W60)=0,"Not started",IF(COUNTA(E60:J60,P60:W60)<14,"Incomplete",IF((AND(F60<>"",F60&""<>"0",TRIM(K60)="")+AND(G60<>"",G60&""<>"0",TRIM(L60)="")+AND(H60<>"",H60&""<>"0",TRIM(M60)="")+AND(I60<>"",I60&""<>"0",TRIM(N60)="")+AND(J60<>"",J60&""<>"0",TRIM(O60)=""))>0,"Add evidence","Complete"))) | Z60: 1120 | AA60: Managing Directors and Chief Executives | AB60: 112 | AC60: Managing Directors and Chief Executives | AD60: 1 | AE60: Managers | AF60: Not defined | AG60: 1219.50
A61: 59 | B61: 1120.9900 | C61: Managing Directors and Chief Executives, Others | D61: Working Proprietors and Directors, Other Workers plan, organize, control, co-ordinate and supervise activities of public or private organizations, wholly or partially owned by them or on behalf of others, engaged in generating, transmitting and distributing electricity; producing and supplying gas, purifying and supplying water and providing related services not elsewhere classified. | Y61: =IF(COUNTA(E61:J61,P61:W61)=0,"Not started",IF(COUNTA(E61:J61,P61:W61)<14,"Incomplete",IF((AND(F61<>"",F61&""<>"0",TRIM(K61)="")+AND(G61<>"",G61&""<>"0",TRIM(L61)="")+AND(H61<>"",H61&""<>"0",TRIM(M61)="")+AND(I61<>"",I61&""<>"0",TRIM(N61)="")+AND(J61<>"",J61&""<>"0",TRIM(O61)=""))>0,"Add evidence","Complete"))) | Z61: 1120 | AA61: Managing Directors and Chief Executives | AB61: 112 | AC61: Managing Directors and Chief Executives | AD61: 1 | AE61: Managers | AF61: Not defined | AG61: 1211.90
A62: 60 | B62: 1211.0100 | C62: General Manager, Bank | D62: General Manager, Bank organizes, controls and supervises, within authority delegated, activities of a private or public bank or one or more of its departments or branches. Is designated according to authority delegated or work performed such as: AGENT (BANK) SUB-AGENT (BANK) | Y62: =IF(COUNTA(E62:J62,P62:W62)=0,"Not started",IF(COUNTA(E62:J62,P62:W62)<14,"Incomplete",IF((AND(F62<>"",F62&""<>"0",TRIM(K62)="")+AND(G62<>"",G62&""<>"0",TRIM(L62)="")+AND(H62<>"",H62&""<>"0",TRIM(M62)="")+AND(I62<>"",I62&""<>"0",TRIM(N62)="")+AND(J62<>"",J62&""<>"0",TRIM(O62)=""))>0,"Add evidence","Complete"))) | Z62: 1211 | AA62: Finance Managers | AB62: 121 | AC62: Business Services and Administration Managers | AD62: 1 | AE62: Managers | AF62: Not defined | AG62: 1307.10
A63: 61 | B63: 1211.0200 | C63: General Manager, Insurance | D63: General Manager, Insurance organizes, controls and supervises, within authority delegated, activities of a private or public organization or one or more of its departments or branches, engaged in life, fire, accident, marine and other general insurance business. | Y63: =IF(COUNTA(E63:J63,P63:W63)=0,"Not started",IF(COUNTA(E63:J63,P63:W63)<14,"Incomplete",IF((AND(F63<>"",F63&""<>"0",TRIM(K63)="")+AND(G63<>"",G63&""<>"0",TRIM(L63)="")+AND(H63<>"",H63&""<>"0",TRIM(M63)="")+AND(I63<>"",I63&""<>"0",TRIM(N63)="")+AND(J63<>"",J63&""<>"0",TRIM(O63)=""))>0,"Add evidence","Complete"))) | Z63: 1211 | AA63: Finance Managers | AB63: 121 | AC63: Business Services and Administration Managers | AD63: 1 | AE63: Managers | AF63: Not defined | AG63: 1307.20
A64: 62 | B64: 1211.0300 | C64: Purser, Ship | D64: Purser, Ship deals with correspondence and accounts relating to a ship. Keeps charge of all accounts and pay of the ship's personnel. Checks reports of Clerks and pays of crew and maintains their pay rolls. Prepares portage bills and ship's 30 articles (contracts). Collects mail and distributes to passengers, officers and crew. May supervise stowing or removal of luggage from holds in conjunction with Chief Officer, Ship or Officer on Watch. May collect valuables of passengers for safe custody in passenger ships. May arrange parties and other entertainment for passengers and generally acts as a host. | Y64: =IF(COUNTA(E64:J64,P64:W64)=0,"Not started",IF(COUNTA(E64:J64,P64:W64)<14,"Incomplete",IF((AND(F64<>"",F64&""<>"0",TRIM(K64)="")+AND(G64<>"",G64&""<>"0",TRIM(L64)="")+AND(H64<>"",H64&""<>"0",TRIM(M64)="")+AND(I64<>"",I64&""<>"0",TRIM(N64)="")+AND(J64<>"",J64&""<>"0",TRIM(O64)=""))>0,"Add evidence","Complete"))) | Z64: 1211 | AA64: Finance Managers | AB64: 121 | AC64: Business Services and Administration Managers | AD64: 1 | AE64: Managers | AF64: Not defined | AG64: 1231.10
...

Sheet Progress
A1: Coding progress
A2: =IF(Instructions!$C$6="","Coder ID not entered on Instructions sheet","Coder ID: "&Instructions!$C$6)
A4: Division | B4: Title | C4: Occupations | D4: Complete | E4: Add evidence | F4: Incomplete | G4: Not started | H4: % complete
A5: 1 | B5: Managers | C5: =COUNTIF(Coding!$AD$3:$AD$3452,A5) | D5: =COUNTIFS(Coding!$AD$3:$AD$3452,A5,Coding!$Y$3:$Y$3452,"Complete") | E5: =COUNTIFS(Coding!$AD$3:$AD$3452,A5,Coding!$Y$3:$Y$3452,"Add evidence") | F5: =COUNTIFS(Coding!$AD$3:$AD$3452,A5,Coding!$Y$3:$Y$3452,"Incomplete") | G5: =COUNTIFS(Coding!$AD$3:$AD$3452,A5,Coding!$Y$3:$Y$3452,"Not started") | H5: =IF(C5=0,0,D5/C5)
A6: 2 | B6: Professionals | C6: =COUNTIF(Coding!$AD$3:$AD$3452,A6) | D6: =COUNTIFS(Coding!$AD$3:$AD$3452,A6,Coding!$Y$3:$Y$3452,"Complete") | E6: =COUNTIFS(Coding!$AD$3:$AD$3452,A6,Coding!$Y$3:$Y$3452,"Add evidence") | F6: =COUNTIFS(Coding!$AD$3:$AD$3452,A6,Coding!$Y$3:$Y$3452,"Incomplete") | G6: =COUNTIFS(Coding!$AD$3:$AD$3452,A6,Coding!$Y$3:$Y$3452,"Not started") | H6: =IF(C6=0,0,D6/C6)
A7: 3 | B7: Technicians and Associate Professionals | C7: =COUNTIF(Coding!$AD$3:$AD$3452,A7) | D7: =COUNTIFS(Coding!$AD$3:$AD$3452,A7,Coding!$Y$3:$Y$3452,"Complete") | E7: =COUNTIFS(Coding!$AD$3:$AD$3452,A7,Coding!$Y$3:$Y$3452,"Add evidence") | F7: =COUNTIFS(Coding!$AD$3:$AD$3452,A7,Coding!$Y$3:$Y$3452,"Incomplete") | G7: =COUNTIFS(Coding!$AD$3:$AD$3452,A7,Coding!$Y$3:$Y$3452,"Not started") | H7: =IF(C7=0,0,D7/C7)
A8: 4 | B8: Clerks/Clerical Support Workers | C8: =COUNTIF(Coding!$AD$3:$AD$3452,A8) | D8: =COUNTIFS(Coding!$AD$3:$AD$3452,A8,Coding!$Y$3:$Y$3452,"Complete") | E8: =COUNTIFS(Coding!$AD$3:$AD$3452,A8,Coding!$Y$3:$Y$3452,"Add evidence") | F8: =COUNTIFS(Coding!$AD$3:$AD$3452,A8,Coding!$Y$3:$Y$3452,"Incomplete") | G8: =COUNTIFS(Coding!$AD$3:$AD$3452,A8,Coding!$Y$3:$Y$3452,"Not started") | H8: =IF(C8=0,0,D8/C8)
A9: 5 | B9: Service and Sales Workers | C9: =COUNTIF(Coding!$AD$3:$AD$3452,A9) | D9: =COUNTIFS(Coding!$AD$3:$AD$3452,A9,Coding!$Y$3:$Y$3452,"Complete") | E9: =COUNTIFS(Coding!$AD$3:$AD$3452,A9,Coding!$Y$3:$Y$3452,"Add evidence") | F9: =COUNTIFS(Coding!$AD$3:$AD$3452,A9,Coding!$Y$3:$Y$3452,"Incomplete") | G9: =COUNTIFS(Coding!$AD$3:$AD$3452,A9,Coding!$Y$3:$Y$3452,"Not started") | H9: =IF(C9=0,0,D9/C9)
A10: 6 | B10: Skilled Agricultural, Forestry and Fishery Workers | C10: =COUNTIF(Coding!$AD$3:$AD$3452,A10) | D10: =COUNTIFS(Coding!$AD$3:$AD$3452,A10,Coding!$Y$3:$Y$3452,"Complete") | E10: =COUNTIFS(Coding!$AD$3:$AD$3452,A10,Coding!$Y$3:$Y$3452,"Add evidence") | F10: =COUNTIFS(Coding!$AD$3:$AD$3452,A10,Coding!$Y$3:$Y$3452,"Incomplete") | G10: =COUNTIFS(Coding!$AD$3:$AD$3452,A10,Coding!$Y$3:$Y$3452,"Not started") | H10: =IF(C10=0,0,D10/C10)
A11: 7 | B11: Craft and Related Trades Workers | C11: =COUNTIF(Coding!$AD$3:$AD$3452,A11) | D11: =COUNTIFS(Coding!$AD$3:$AD$3452,A11,Coding!$Y$3:$Y$3452,"Complete") | E11: =COUNTIFS(Coding!$AD$3:$AD$3452,A11,Coding!$Y$3:$Y$3452,"Add evidence") | F11: =COUNTIFS(Coding!$AD$3:$AD$3452,A11,Coding!$Y$3:$Y$3452,"Incomplete") | G11: =COUNTIFS(Coding!$AD$3:$AD$3452,A11,Coding!$Y$3:$Y$3452,"Not started") | H11: =IF(C11=0,0,D11/C11)
A12: 8 | B12: Plant and Machine Operators, and Assemblers | C12: =COUNTIF(Coding!$AD$3:$AD$3452,A12) | D12: =COUNTIFS(Coding!$AD$3:$AD$3452,A12,Coding!$Y$3:$Y$3452,"Complete") | E12: =COUNTIFS(Coding!$AD$3:$AD$3452,A12,Coding!$Y$3:$Y$3452,"Add evidence") | F12: =COUNTIFS(Coding!$AD$3:$AD$3452,A12,Coding!$Y$3:$Y$3452,"Incomplete") | G12: =COUNTIFS(Coding!$AD$3:$AD$3452,A12,Coding!$Y$3:$Y$3452,"Not started") | H12: =IF(C12=0,0,D12/C12)
A13: 9 | B13: Elementary Occupations | C13: =COUNTIF(Coding!$AD$3:$AD$3452,A13) | D13: =COUNTIFS(Coding!$AD$3:$AD$3452,A13,Coding!$Y$3:$Y$3452,"Complete") | E13: =COUNTIFS(Coding!$AD$3:$AD$3452,A13,Coding!$Y$3:$Y$3452,"Add evidence") | F13: =COUNTIFS(Coding!$AD$3:$AD$3452,A13,Coding!$Y$3:$Y$3452,"Incomplete") | G13: =COUNTIFS(Coding!$AD$3:$AD$3452,A13,Coding!$Y$3:$Y$3452,"Not started") | H13: =IF(C13=0,0,D13/C13)
B14: All divisions | C14: =SUM(C5:C13) | D14: =SUM(D5:D13) | E14: =SUM(E5:E13) | F14: =SUM(F5:F13) | G14: =SUM(G5:G13) | H14: =IF(C14=0,0,D14/C14)

Sheet Lists
A1: Yes | B1: 0 | C1: 1 | D1: 0 | E1: Core | F1: More
A2: Partly | B2: 1 | C2: 2 | D2: 1 | E2: Supporting | F2: Same
A3: No | B3: 2 | C3: 3 | D3: 2 | E3: Not relevant | F3: Less
B4: 3 | D4: 3
B5: 4 | D5: 4
D6: 5
D7: 6
D8: 7
D9: 8
D10: 9
D11: 10
